<?xml version="1.0" ?>
<!-- =================================================================================== -->
<!-- |    This document was autogenerated by xacro from sr1_3dof_urdf.xacro            | -->
<!-- |    EDITING THIS FILE BY HAND IS NOT RECOMMENDED                                 | -->
<!-- =================================================================================== -->
<robot name="sr1_3dof_urdf">
  <material name="silver">
    <color rgba="0.700 0.700 0.700 1.000"/>
  </material>
  <transmission name="joint2_tran">
    <type>transmission_interface/SimpleTransmission</type>
    <joint name="joint2">
      <hardwareInterface>hardware_interface/EffortJointInterface</hardwareInterface>
    </joint>
    <actuator name="joint2_actr">
      <hardwareInterface>hardware_interface/EffortJointInterface</hardwareInterface>
      <mechanicalReduction>1</mechanicalReduction>
    </actuator>
  </transmission>
  <transmission name="joint3_tran">
    <type>transmission_interface/SimpleTransmission</type>
    <joint name="joint3">
      <hardwareInterface>hardware_interface/EffortJointInterface</hardwareInterface>
    </joint>
    <actuator name="joint3_actr">
      <hardwareInterface>hardware_interface/EffortJointInterface</hardwareInterface>
      <mechanicalReduction>1</mechanicalReduction>
    </actuator>
  </transmission>
  <transmission name="joint1_tran">
    <type>transmission_interface/SimpleTransmission</type>
    <joint name="joint1">
      <hardwareInterface>hardware_interface/EffortJointInterface</hardwareInterface>
    </joint>
    <actuator name="joint1_actr">
      <hardwareInterface>hardware_interface/EffortJointInterface</hardwareInterface>
      <mechanicalReduction>1</mechanicalReduction>
    </actuator>
  </transmission>
  <gazebo>
    <plugin filename="libgazebo_ros_control.so" name="control"/>
  </gazebo>
  <gazebo reference="base_link">
    <material>Gazebo/Silver</material>
    <mu1>0.2</mu1>
    <mu2>0.2</mu2>
    <selfCollide>true</selfCollide>
    <gravity>true</gravity>
  </gazebo>
  <gazebo reference="standM20_1">
    <material>Gazebo/Silver</material>
    <mu1>0.2</mu1>
    <mu2>0.2</mu2>
    <selfCollide>true</selfCollide>
  </gazebo>
  <gazebo reference="servo1_1">
    <material>Gazebo/Silver</material>
    <mu1>0.2</mu1>
    <mu2>0.2</mu2>
    <selfCollide>true</selfCollide>
  </gazebo>
  <gazebo reference="arm_servo2_1">
    <material>Gazebo/Silver</material>
    <mu1>0.2</mu1>
    <mu2>0.2</mu2>
    <selfCollide>true</selfCollide>
  </gazebo>
  <gazebo reference="servo2_1">
    <material>Gazebo/Silver</material>
    <mu1>0.2</mu1>
    <mu2>0.2</mu2>
    <selfCollide>true</selfCollide>
  </gazebo>
  <gazebo reference="servo_suit2_1">
    <material>Gazebo/Silver</material>
    <mu1>0.2</mu1>
    <mu2>0.2</mu2>
    <selfCollide>true</selfCollide>
  </gazebo>
  <gazebo reference="link2_1">
    <material>Gazebo/Silver</material>
    <mu1>0.2</mu1>
    <mu2>0.2</mu2>
    <selfCollide>true</selfCollide>
  </gazebo>
  <gazebo reference="servo_suit3_1">
    <material>Gazebo/Silver</material>
    <mu1>0.2</mu1>
    <mu2>0.2</mu2>
    <selfCollide>true</selfCollide>
  </gazebo>
  <gazebo reference="servo3_1">
    <material>Gazebo/Silver</material>
    <mu1>0.2</mu1>
    <mu2>0.2</mu2>
    <selfCollide>true</selfCollide>
  </gazebo>
  <gazebo reference="arm_servo3_1">
    <material>Gazebo/Silver</material>
    <mu1>0.2</mu1>
    <mu2>0.2</mu2>
    <selfCollide>true</selfCollide>
  </gazebo>
  <gazebo reference="gripper_1">
    <material>Gazebo/Silver</material>
    <mu1>0.2</mu1>
    <mu2>0.2</mu2>
    <selfCollide>true</selfCollide>
  </gazebo>
  <gazebo reference="arm_servo1_1">
    <material>Gazebo/Silver</material>
    <mu1>0.2</mu1>
    <mu2>0.2</mu2>
    <selfCollide>true</selfCollide>
  </gazebo>
  <gazebo reference="link1_1">
    <material>Gazebo/Silver</material>
    <mu1>0.2</mu1>
    <mu2>0.2</mu2>
    <selfCollide>true</selfCollide>
  </gazebo>
  <gazebo reference="Pointer_v2_1">
    <material>Gazebo/Silver</material>
    <mu1>0.2</mu1>
    <mu2>0.2</mu2>
    <selfCollide>true</selfCollide>
  </gazebo>
  <link name="base_link">
    <inertial>
      <origin rpy="0 0 0" xyz="-0.0002513306601796678 0.00013267508841249576 0.001059046789686807"/>
      <mass value="1.4414312260182711"/>
      <inertia ixx="0.005341" ixy="-0.0" ixz="-0.0" iyy="0.010675" iyz="0.0" izz="0.016014"/>
    </inertial>
    <visual>
      <origin rpy="0 0 0" xyz="0 0 0"/>
      <geometry>
        <mesh filename="package://sr1_3dof_urdf_description/meshes/base_link.stl" scale="0.001 0.001 0.001"/>
      </geometry>
      <material name="silver"/>
    </visual>
    <collision>
      <origin rpy="0 0 0" xyz="0 0 0"/>
      <geometry>
        <mesh filename="package://sr1_3dof_urdf_description/meshes/base_link.stl" scale="0.001 0.001 0.001"/>
      </geometry>
    </collision>
  </link>
  <link name="standM20_1">
    <inertial>
      <origin rpy="0 0 0" xyz="-3.306599347871475e-07 -3.249115877925618e-07 0.01000004678968681"/>
      <mass value="0.0015683260779925593"/>
      <inertia ixx="0.0" ixy="0.0" ixz="0.0" iyy="0.0" iyz="0.0" izz="0.0"/>
    </inertial>
    <visual>
      <origin rpy="0 0 0" xyz="0.024751 -0.004883 -0.002559"/>
      <geometry>
        <mesh filename="package://sr1_3dof_urdf_description/meshes/standM20_1.stl" scale="0.001 0.001 0.001"/>
      </geometry>
      <material name="silver"/>
    </visual>
    <collision>
      <origin rpy="0 0 0" xyz="0.024751 -0.004883 -0.002559"/>
      <geometry>
        <mesh filename="package://sr1_3dof_urdf_description/meshes/standM20_1.stl" scale="0.001 0.001 0.001"/>
      </geometry>
    </collision>
  </link>
  <link name="servo1_1">
    <inertial>
      <origin rpy="0 0 0" xyz="0.024429239244436834 -0.004750324911591204 -0.008932139547487766"/>
      <mass value="0.23103338687475486"/>
      <inertia ixx="3.2e-05" ixy="-0.0" ixz="0.0" iyy="5.8e-05" iyz="0.0" izz="4.1e-05"/>
    </inertial>
    <visual>
      <origin rpy="0 0 0" xyz="0.024751 -0.004883 -0.022559"/>
      <geometry>
        <mesh filename="package://sr1_3dof_urdf_description/meshes/servo1_1.stl" scale="0.001 0.001 0.001"/>
      </geometry>
      <material name="silver"/>
    </visual>
    <collision>
      <origin rpy="0 0 0" xyz="0.024751 -0.004883 -0.022559"/>
      <geometry>
        <mesh filename="package://sr1_3dof_urdf_description/meshes/servo1_1.stl" scale="0.001 0.001 0.001"/>
      </geometry>
    </collision>
  </link>
  <link name="arm_servo2_1">
    <inertial>
      <origin rpy="0 0 0" xyz="5.963469627071061e-07 0.0018134751183520523 -0.003929292208864413"/>
      <mass value="0.0016195799801192233"/>
      <inertia ixx="0.0" ixy="0.0" ixz="0.0" iyy="0.0" iyz="-0.0" izz="0.0"/>
    </inertial>
    <visual>
      <origin rpy="0 0 0" xyz="-0.01564 0.022567 -0.065409"/>
      <geometry>
        <mesh filename="package://sr1_3dof_urdf_description/meshes/arm_servo2_1.stl" scale="0.001 0.001 0.001"/>
      </geometry>
      <material name="silver"/>
    </visual>
    <collision>
      <origin rpy="0 0 0" xyz="-0.01564 0.022567 -0.065409"/>
      <geometry>
        <mesh filename="package://sr1_3dof_urdf_description/meshes/arm_servo2_1.stl" scale="0.001 0.001 0.001"/>
      </geometry>
    </collision>
  </link>
  <link name="servo2_1">
    <inertial>
      <origin rpy="0 0 0" xyz="-3.3066017973357176e-07 0.0017291344703287068 4.678937873259237e-08"/>
      <mass value="0.00045126850039796834"/>
      <inertia ixx="0.0" ixy="-0.0" ixz="0.0" iyy="0.0" iyz="-0.0" izz="0.0"/>
    </inertial>
    <visual>
      <origin rpy="0 0 0" xyz="-0.01564 0.020067 -0.065409"/>
      <geometry>
        <mesh filename="package://sr1_3dof_urdf_description/meshes/servo2_1.stl" scale="0.001 0.001 0.001"/>
      </geometry>
      <material name="silver"/>
    </visual>
    <collision>
      <origin rpy="0 0 0" xyz="-0.01564 0.020067 -0.065409"/>
      <geometry>
        <mesh filename="package://sr1_3dof_urdf_description/meshes/servo2_1.stl" scale="0.001 0.001 0.001"/>
      </geometry>
    </collision>
  </link>
  <link name="servo_suit2_1">
    <inertial>
      <origin rpy="0 0 0" xyz="-0.004044486872933144 0.015156467820661105 -0.013874953115322233"/>
      <mass value="0.025845994288563736"/>
      <inertia ixx="4e-06" ixy="-0.0" ixz="0.0" iyy="2e-06" iyz="0.0" izz="3e-06"/>
    </inertial>
    <visual>
      <origin rpy="0 0 0" xyz="-0.01564 0.006317 -0.084659"/>
      <geometry>
        <mesh filename="package://sr1_3dof_urdf_description/meshes/servo_suit2_1.stl" scale="0.001 0.001 0.001"/>
      </geometry>
      <material name="silver"/>
    </visual>
    <collision>
      <origin rpy="0 0 0" xyz="-0.01564 0.006317 -0.084659"/>
      <geometry>
        <mesh filename="package://sr1_3dof_urdf_description/meshes/servo_suit2_1.stl" scale="0.001 0.001 0.001"/>
      </geometry>
    </collision>
  </link>
  <link name="link2_1">
    <inertial>
      <origin rpy="0 0 0" xyz="0.000890624711466375 0.0014996740380796366 0.03525004678968814"/>
      <mass value="0.024002279759971108"/>
      <inertia ixx="1.3e-05" ixy="-0.0" ixz="0.0" iyy="1.4e-05" iyz="0.0" izz="1e-06"/>
    </inertial>
    <visual>
      <origin rpy="0 0 0" xyz="-0.01569 0.003317 -0.056909"/>
      <geometry>
        <mesh filename="package://sr1_3dof_urdf_description/meshes/link2_1.stl" scale="0.001 0.001 0.001"/>
      </geometry>
      <material name="silver"/>
    </visual>
    <collision>
      <origin rpy="0 0 0" xyz="-0.01569 0.003317 -0.056909"/>
      <geometry>
        <mesh filename="package://sr1_3dof_urdf_description/meshes/link2_1.stl" scale="0.001 0.001 0.001"/>
      </geometry>
    </collision>
  </link>
  <link name="servo_suit3_1">
    <inertial>
      <origin rpy="0 0 0" xyz="-0.004094486872933123 0.012156467820661107 0.013875046884677764"/>
      <mass value="0.025845994288563736"/>
      <inertia ixx="4e-06" ixy="-0.0" ixz="0.0" iyy="2e-06" iyz="0.0" izz="3e-06"/>
    </inertial>
    <visual>
      <origin rpy="0 0 0" xyz="-0.01569 0.003317 -0.099659"/>
      <geometry>
        <mesh filename="package://sr1_3dof_urdf_description/meshes/servo_suit3_1.stl" scale="0.001 0.001 0.001"/>
      </geometry>
      <material name="silver"/>
    </visual>
    <collision>
      <origin rpy="0 0 0" xyz="-0.01569 0.003317 -0.099659"/>
      <geometry>
        <mesh filename="package://sr1_3dof_urdf_description/meshes/servo_suit3_1.stl" scale="0.001 0.001 0.001"/>
      </geometry>
    </collision>
  </link>
  <link name="servo3_1">
    <inertial>
      <origin rpy="0 0 0" xyz="-3.306601796988773e-07 -0.01202086552967125 0.019250046789994785"/>
      <mass value="0.00045126850039796834"/>
      <inertia ixx="0.0" ixy="0.0" ixz="0.0" iyy="0.0" iyz="0.0" izz="0.0"/>
    </inertial>
    <visual>
      <origin rpy="0 0 0" xyz="-0.01569 0.006317 -0.099659"/>
      <geometry>
        <mesh filename="package://sr1_3dof_urdf_description/meshes/servo3_1.stl" scale="0.001 0.001 0.001"/>
      </geometry>
      <material name="silver"/>
    </visual>
    <collision>
      <origin rpy="0 0 0" xyz="-0.01569 0.006317 -0.099659"/>
      <geometry>
        <mesh filename="package://sr1_3dof_urdf_description/meshes/servo3_1.stl" scale="0.001 0.001 0.001"/>
      </geometry>
    </collision>
  </link>
  <link name="arm_servo3_1">
    <inertial>
      <origin rpy="0 0 0" xyz="-1.2576673221603718e-06 -0.0006865248816479257 0.003929385788237788"/>
      <mass value="0.0016195799801192233"/>
      <inertia ixx="0.0" ixy="-0.0" ixz="0.0" iyy="0.0" iyz="0.0" izz="0.0"/>
    </inertial>
    <visual>
      <origin rpy="0 0 0" xyz="-0.01569 0.020067 -0.118909"/>
      <geometry>
        <mesh filename="package://sr1_3dof_urdf_description/meshes/arm_servo3_1.stl" scale="0.001 0.001 0.001"/>
      </geometry>
      <material name="silver"/>
    </visual>
    <collision>
      <origin rpy="0 0 0" xyz="-0.01569 0.020067 -0.118909"/>
      <geometry>
        <mesh filename="package://sr1_3dof_urdf_description/meshes/arm_servo3_1.stl" scale="0.001 0.001 0.001"/>
      </geometry>
    </collision>
  </link>
  <link name="gripper_1">
    <inertial>
      <origin rpy="0 0 0" xyz="1.5088800062804109e-05 0.005462688544684565 0.02525541881541478"/>
      <mass value="0.019340723457636558"/>
      <inertia ixx="6e-06" ixy="-0.0" ixz="-0.0" iyy="4e-06" iyz="-2e-06" izz="1e-06"/>
    </inertial>
    <visual>
      <origin rpy="0 0 0" xyz="-0.01569 0.022567 -0.118909"/>
      <geometry>
        <mesh filename="package://sr1_3dof_urdf_description/meshes/gripper_1.stl" scale="0.001 0.001 0.001"/>
      </geometry>
      <material name="silver"/>
    </visual>
    <collision>
      <origin rpy="0 0 0" xyz="-0.01569 0.022567 -0.118909"/>
      <geometry>
        <mesh filename="package://sr1_3dof_urdf_description/meshes/gripper_1.stl" scale="0.001 0.001 0.001"/>
      </geometry>
    </collision>
  </link>
  <link name="arm_servo1_1">
    <inertial>
      <origin rpy="0 0 0" xyz="2.3104853023488137e-06 7.551504635582137e-07 0.0007555080204811118"/>
      <mass value="0.0059977269324000045"/>
      <inertia ixx="0.0" ixy="0.0" ixz="-0.0" iyy="0.0" iyz="-0.0" izz="1e-06"/>
    </inertial>
    <visual>
      <origin rpy="0 0 0" xyz="0.01036 -0.000133 -0.038559"/>
      <geometry>
        <mesh filename="package://sr1_3dof_urdf_description/meshes/arm_servo1_1.stl" scale="0.001 0.001 0.001"/>
      </geometry>
      <material name="silver"/>
    </visual>
    <collision>
      <origin rpy="0 0 0" xyz="0.01036 -0.000133 -0.038559"/>
      <geometry>
        <mesh filename="package://sr1_3dof_urdf_description/meshes/arm_servo1_1.stl" scale="0.001 0.001 0.001"/>
      </geometry>
    </collision>
  </link>
  <link name="link1_1">
    <inertial>
      <origin rpy="0 0 0" xyz="0.014528279310683848 0.000658203149917335 0.004057458413534366"/>
      <mass value="0.07794699374847427"/>
      <inertia ixx="2.3e-05" ixy="-1e-06" ixz="-3e-06" iyy="2.4e-05" iyz="-0.0" izz="3.7e-05"/>
    </inertial>
    <visual>
      <origin rpy="0 0 0" xyz="0.01036 -0.000133 -0.040909"/>
      <geometry>
        <mesh filename="package://sr1_3dof_urdf_description/meshes/link1_1.stl" scale="0.001 0.001 0.001"/>
      </geometry>
      <material name="silver"/>
    </visual>
    <collision>
      <origin rpy="0 0 0" xyz="0.01036 -0.000133 -0.040909"/>
      <geometry>
        <mesh filename="package://sr1_3dof_urdf_description/meshes/link1_1.stl" scale="0.001 0.001 0.001"/>
      </geometry>
    </collision>
  </link>
  <link name="Pointer_v2_1">
    <inertial>
      <origin rpy="0 0 0" xyz="-3.306601796641828e-07 0.0014996750884122129 0.0025553604984562828"/>
      <mass value="0.0009058546002820461"/>
      <inertia ixx="0.0" ixy="-0.0" ixz="0.0" iyy="0.0" iyz="0.0" izz="0.0"/>
    </inertial>
    <visual>
      <origin rpy="0 0 0" xyz="-0.01569 0.003317 -0.165693"/>
      <geometry>
        <mesh filename="package://sr1_3dof_urdf_description/meshes/Pointer_v2_1.stl" scale="0.001 0.001 0.001"/>
      </geometry>
      <material name="silver"/>
    </visual>
    <collision>
      <origin rpy="0 0 0" xyz="-0.01569 0.003317 -0.165693"/>
      <geometry>
        <mesh filename="package://sr1_3dof_urdf_description/meshes/Pointer_v2_1.stl" scale="0.001 0.001 0.001"/>
      </geometry>
    </collision>
  </link>
  <joint name="Rigid24" type="fixed">
    <origin rpy="0 0 0" xyz="-0.024751 0.004883 0.002559"/>
    <parent link="base_link"/>
    <child link="standM20_1"/>
  </joint>
  <joint name="Rigid25" type="fixed">
    <origin rpy="0 0 0" xyz="0.0 0.0 0.02"/>
    <parent link="standM20_1"/>
    <child link="servo1_1"/>
  </joint>
  <joint name="Rigid28" type="fixed">
    <origin rpy="0 0 0" xyz="0.026 -0.0227 0.0245"/>
    <parent link="link1_1"/>
    <child link="arm_servo2_1"/>
  </joint>
  <joint name="joint2" type="revolute">
    <origin rpy="0 0 0" xyz="0.0 0.0025 0.0"/>
    <parent link="arm_servo2_1"/>
    <child link="servo2_1"/>
    <axis xyz="0.0 -1.0 -0.0"/>
    <limit effort="100" lower="-1.570796" upper="1.570796" velocity="100"/>
  </joint>
  <joint name="Rigid30" type="fixed">
    <origin rpy="0 0 0" xyz="0.0 0.01375 0.01925"/>
    <parent link="servo2_1"/>
    <child link="servo_suit2_1"/>
  </joint>
  <joint name="Rigid31" type="fixed">
    <origin rpy="0 0 0" xyz="5e-05 0.003 -0.02775"/>
    <parent link="servo_suit2_1"/>
    <child link="link2_1"/>
  </joint>
  <joint name="Rigid32" type="fixed">
    <origin rpy="0 0 0" xyz="0.0 0.0 0.04275"/>
    <parent link="link2_1"/>
    <child link="servo_suit3_1"/>
  </joint>
  <joint name="Rigid33" type="fixed">
    <origin rpy="0 0 0" xyz="0.0 -0.003 0.0"/>
    <parent link="servo_suit3_1"/>
    <child link="servo3_1"/>
  </joint>
  <joint name="joint3" type="revolute">
    <origin rpy="0 0 0" xyz="0.0 -0.01375 0.01925"/>
    <parent link="servo3_1"/>
    <child link="arm_servo3_1"/>
    <axis xyz="0.0 -1.0 -0.0"/>
    <limit effort="100" lower="-1.570796" upper="1.570796" velocity="100"/>
  </joint>
  <joint name="Rigid35" type="fixed">
    <origin rpy="0 0 0" xyz="0.0 -0.0025 0.0"/>
    <parent link="arm_servo3_1"/>
    <child link="gripper_1"/>
  </joint>
  <joint name="joint1" type="revolute">
    <origin rpy="0 0 0" xyz="0.014391 -0.00475 0.016"/>
    <parent link="servo1_1"/>
    <child link="arm_servo1_1"/>
    <axis xyz="0.0 -0.0 1.0"/>
    <limit effort="100" lower="-1.570796" upper="1.570796" velocity="100"/>
  </joint>
  <joint name="Rigid37" type="fixed">
    <origin rpy="0 0 0" xyz="0.0 0.0 0.00235"/>
    <parent link="arm_servo1_1"/>
    <child link="link1_1"/>
  </joint>
  <joint name="point_joint" type="fixed">
    <origin rpy="0 0 0" xyz="0.0 0.01925 0.046784"/>
    <parent link="gripper_1"/>
    <child link="Pointer_v2_1"/>
  </joint>
</robot>
